Workbook

Sheet Plan
A1: Long-Term Portfolio Plan - Moderate Growth (Robinhood)
A2: Blue = input you can change | Black = formula | Green = link | Yellow = key assumption. Illustrative template, not investment advice.
A3: Inputs
A4: Monthly contribution ($) | B4: 1500 | C4: You said over $1,000/month; $1,500 assumed - change it
A5: Current portfolio value ($) | B5: =Holdings!G17 -> 0 | C5: Auto-filled from the Holdings sheet
A6: Annual increase in contributions | B6: 0.03 | C6: ASSUMPTION: raises track with income
A7: Inflation | B7: 0.025 | C7: ASSUMPTION: used for "today's dollars" values
A8: Rebalance drift tolerance (+/- pts) | B8: 0.05 | C8: Flag a holding when it drifts this far from target
A9: Low / high case return spread (+/- pts) | B9: 0.02 | C9: Shifts expected return for the low and high projections
A11: Expected return by asset class (assumptions - long-run guesses, not guarantees)
A12: Asset class | B12: Expected annual return | C12: Target % (sum) | D12: Role
A13: US Equity ETF | B13: 0.07 | C13: =SUMIF($C$22:$C$32,A13,$D$22:$D$32) -> 0.33 | D13: Core growth
A14: Intl Equity ETF | B14: 0.065 | C14: =SUMIF($C$22:$C$32,A14,$D$22:$D$32) -> 0.12 | D14: Diversification
A15: Dividend ETF | B15: 0.065 | C15: =SUMIF($C$22:$C$32,A15,$D$22:$D$32) -> 0.05 | D15: Income / stability
A16: Individual Stocks | B16: 0.08 | C16: =SUMIF($C$22:$C$32,A16,$D$22:$D$32) -> 0.3 | D16: Higher conviction, higher risk
A17: Bonds | B17: 0.04 | C17: =SUMIF($C$22:$C$32,A17,$D$22:$D$32) -> 0.15 | D17: Ballast
A18: Cash / T-Bills | B18: 0.035 | C18: =SUMIF($C$22:$C$32,A18,$D$22:$D$32) -> 0.05 | D18: Dry powder
A20: Target allocation (edit tickers / weights - must total 100%)
A21: Ticker | B21: Name | C21: Asset class | D21: Target % | E21: Expected return | F21: Monthly $ | G21: Annual $
A22: VTI | B22: Vanguard Total Stock Market ETF | C22: US Equity ETF | D22: 0.33 | E22: =IFERROR(INDEX($B$13:$B$18,MATCH(C22,$A$13:$A$18,0)),0) -> 0.07 | F22: =D22*$B$4 -> 495 | G22: =F22*12 -> 5940
A23: VXUS | B23: Vanguard Total International Stock ETF | C23: Intl Equity ETF | D23: 0.12 | E23: =IFERROR(INDEX($B$13:$B$18,MATCH(C23,$A$13:$A$18,0)),0) -> 0.065 | F23: =D23*$B$4 -> 180 | G23: =F23*12 -> 2160
A24: SCHD | B24: Schwab US Dividend Equity ETF | C24: Dividend ETF | D24: 0.05 | E24: =IFERROR(INDEX($B$13:$B$18,MATCH(C24,$A$13:$A$18,0)),0) -> 0.065 | F24: =D24*$B$4 -> 75 | G24: =F24*12 -> 900
A25: NVDA | B25: NVIDIA | C25: Individual Stocks | D25: 0.06 | E25: =IFERROR(INDEX($B$13:$B$18,MATCH(C25,$A$13:$A$18,0)),0) -> 0.08 | F25: =D25*$B$4 -> 90 | G25: =F25*12 -> 1080
A26: MSFT | B26: Microsoft | C26: Individual Stocks | D26: 0.06 | E26: =IFERROR(INDEX($B$13:$B$18,MATCH(C26,$A$13:$A$18,0)),0) -> 0.08 | F26: =D26*$B$4 -> 90 | G26: =F26*12 -> 1080
A27: GOOGL | B27: Alphabet | C27: Individual Stocks | D27: 0.06 | E27: =IFERROR(INDEX($B$13:$B$18,MATCH(C27,$A$13:$A$18,0)),0) -> 0.08 | F27: =D27*$B$4 -> 90 | G27: =F27*12 -> 1080
A28: AMZN | B28: Amazon | C28: Individual Stocks | D28: 0.06 | E28: =IFERROR(INDEX($B$13:$B$18,MATCH(C28,$A$13:$A$18,0)),0) -> 0.08 | F28: =D28*$B$4 -> 90 | G28: =F28*12 -> 1080
A29: BRK.B | B29: Berkshire Hathaway | C29: Individual Stocks | D29: 0.06 | E29: =IFERROR(INDEX($B$13:$B$18,MATCH(C29,$A$13:$A$18,0)),0) -> 0.08 | F29: =D29*$B$4 -> 90 | G29: =F29*12 -> 1080
A30: BND | B30: Vanguard Total Bond Market ETF | C30: Bonds | D30: 0.15 | E30: =IFERROR(INDEX($B$13:$B$18,MATCH(C30,$A$13:$A$18,0)),0) -> 0.04 | F30: =D30*$B$4 -> 225 | G30: =F30*12 -> 2700
A31: SGOV | B31: iShares 0-3 Month Treasury Bond ETF | C31: Cash / T-Bills | D31: 0.05 | E31: =IFERROR(INDEX($B$13:$B$18,MATCH(C31,$A$13:$A$18,0)),0) -> 0.035 | F31: =D31*$B$4 -> 75 | G31: =F31*12 -> 900
B32: (spare slot) | C32: Individual Stocks | D32: 0 | E32: =IFERROR(INDEX($B$13:$B$18,MATCH(C32,$A$13:$A$18,0)),0) -> 0.08 | F32: =D32*$B$4 -> 0 | G32: =F32*12 -> 0
A33: Total / weighted | D33: =SUM(D22:D32) -> 1 | E33: =SUMPRODUCT(D22:D32,E22:E32) -> 0.0659 | F33: =SUM(F22:F32) -> 1500 | G33: =SUM(G22:G32) -> 18000 | H33: =IF(ABS(D33-1)<0.0001,"OK - totals 100%","CHECK: weights must total 100%") -> OK - totals 100%
A35: Key outputs
A36: Expected portfolio return (weighted) | B36: =E33 -> 0.0659
A37: Stock exposure (all equity classes) | B37: =C13+C14+C15+C16 -> 0.8
A38: Individual stocks share of portfolio | B38: =C16 -> 0.3
A39: Largest single-stock position | B39: =SUMPRODUCT(MAX((C22:C32="Individual Stocks")*D22:D32)) -> 0.06 | C39: =IF(B39>0.1,"Note: a single stock above 10% adds concentration risk","")
A40: Base projection - value in 10 years | B40: =INDEX(Projection!C5:C35,MATCH(10,Projection!A5:A35,0)) -> 284409.53
A41: Base projection - value in 20 years | B41: =INDEX(Projection!C5:C35,MATCH(20,Projection!A5:A35,0)) -> 920627.22
A42: Base projection - value in 30 years | B42: =INDEX(Projection!C5:C35,MATCH(30,Projection!A5:A35,0)) -> 2256478.8
A43: ...in today's dollars (30 yrs) | B43: =INDEX(Projection!G5:G35,MATCH(30,Projection!A5:A35,0)) -> 1075759.7
...

Sheet Holdings
A1: Holdings Tracker & This Month's Buy Plan
A2: Enter shares, average cost and current price from your Robinhood account (yellow cells). The plan puts new money into the most underweight holdings - no selling needed.
A3: Example (do not type here): VTI | shares 10 | avg cost $250.00 | price $310.00 -> value $3,100, gain $600 (+24.0%)
A5: Ticker | B5: Name | C5: Asset class | D5: Shares | E5: Avg cost ($) | F5: Price ($) | G5: Market value | H5: Cost basis | I5: Gain / loss | J5: Gain % | K5: Weight | L5: Target | M5: Drift | N5: Status | O5: Gap to target ($) | P5: Buy this month ($) | Q5: Shares to buy
A6: =IF(Plan!A22="","",Plan!A22) -> VTI | B6: =Plan!B22 -> Vanguard Total Stock Market ETF | C6: =Plan!C22 -> US Equity ETF | D6: 0 | E6: 0 | F6: 0 | G6: =D6*F6 -> 0 | H6: =D6*E6 -> 0 | I6: =G6-H6 -> 0 | J6: =IF(H6>0,I6/H6,0) -> 0 | K6: =IF(G$17>0,G6/G$17,0) -> 0 | L6: =Plan!D22 -> 0.33 | M6: =IF(G$17>0,K6-L6,0) -> 0 | N6: =IF(G$17=0,"-",IF(ABS(M6)>Plan!$B$8,IF(M6>0,"Overweight","Underweight"),"OK")) -> - | O6: =MAX(0,L6*(G$17+Plan!$B$4)-G6) -> 495 | P6: =IF(O$17=0,L6*Plan!$B$4,O6/O$17*Plan!$B$4) -> 495 | Q6: =IF(F6>0,P6/F6,"enter price") -> enter price
A7: =IF(Plan!A23="","",Plan!A23) -> VXUS | B7: =Plan!B23 -> Vanguard Total International Stock ETF | C7: =Plan!C23 -> Intl Equity ETF | D7: 0 | E7: 0 | F7: 0 | G7: =D7*F7 -> 0 | H7: =D7*E7 -> 0 | I7: =G7-H7 -> 0 | J7: =IF(H7>0,I7/H7,0) -> 0 | K7: =IF(G$17>0,G7/G$17,0) -> 0 | L7: =Plan!D23 -> 0.12 | M7: =IF(G$17>0,K7-L7,0) -> 0 | N7: =IF(G$17=0,"-",IF(ABS(M7)>Plan!$B$8,IF(M7>0,"Overweight","Underweight"),"OK")) -> - | O7: =MAX(0,L7*(G$17+Plan!$B$4)-G7) -> 180 | P7: =IF(O$17=0,L7*Plan!$B$4,O7/O$17*Plan!$B$4) -> 180 | Q7: =IF(F7>0,P7/F7,"enter price") -> enter price
A8: =IF(Plan!A24="","",Plan!A24) -> SCHD | B8: =Plan!B24 -> Schwab US Dividend Equity ETF | C8: =Plan!C24 -> Dividend ETF | D8: 0 | E8: 0 | F8: 0 | G8: =D8*F8 -> 0 | H8: =D8*E8 -> 0 | I8: =G8-H8 -> 0 | J8: =IF(H8>0,I8/H8,0) -> 0 | K8: =IF(G$17>0,G8/G$17,0) -> 0 | L8: =Plan!D24 -> 0.05 | M8: =IF(G$17>0,K8-L8,0) -> 0 | N8: =IF(G$17=0,"-",IF(ABS(M8)>Plan!$B$8,IF(M8>0,"Overweight","Underweight"),"OK")) -> - | O8: =MAX(0,L8*(G$17+Plan!$B$4)-G8) -> 75 | P8: =IF(O$17=0,L8*Plan!$B$4,O8/O$17*Plan!$B$4) -> 75 | Q8: =IF(F8>0,P8/F8,"enter price") -> enter price
A9: =IF(Plan!A25="","",Plan!A25) -> NVDA | B9: =Plan!B25 -> NVIDIA | C9: =Plan!C25 -> Individual Stocks | D9: 0 | E9: 0 | F9: 0 | G9: =D9*F9 -> 0 | H9: =D9*E9 -> 0 | I9: =G9-H9 -> 0 | J9: =IF(H9>0,I9/H9,0) -> 0 | K9: =IF(G$17>0,G9/G$17,0) -> 0 | L9: =Plan!D25 -> 0.06 | M9: =IF(G$17>0,K9-L9,0) -> 0 | N9: =IF(G$17=0,"-",IF(ABS(M9)>Plan!$B$8,IF(M9>0,"Overweight","Underweight"),"OK")) -> - | O9: =MAX(0,L9*(G$17+Plan!$B$4)-G9) -> 90 | P9: =IF(O$17=0,L9*Plan!$B$4,O9/O$17*Plan!$B$4) -> 90 | Q9: =IF(F9>0,P9/F9,"enter price") -> enter price
A10: =IF(Plan!A26="","",Plan!A26) -> MSFT | B10: =Plan!B26 -> Microsoft | C10: =Plan!C26 -> Individual Stocks | D10: 0 | E10: 0 | F10: 0 | G10: =D10*F10 -> 0 | H10: =D10*E10 -> 0 | I10: =G10-H10 -> 0 | J10: =IF(H10>0,I10/H10,0) -> 0 | K10: =IF(G$17>0,G10/G$17,0) -> 0 | L10: =Plan!D26 -> 0.06 | M10: =IF(G$17>0,K10-L10,0) -> 0 | N10: =IF(G$17=0,"-",IF(ABS(M10)>Plan!$B$8,IF(M10>0,"Overweight","Underweight"),"OK")) -> - | O10: =MAX(0,L10*(G$17+Plan!$B$4)-G10) -> 90 | P10: =IF(O$17=0,L10*Plan!$B$4,O10/O$17*Plan!$B$4) -> 90 | Q10: =IF(F10>0,P10/F10,"enter price") -> enter price
A11: =IF(Plan!A27="","",Plan!A27) -> GOOGL | B11: =Plan!B27 -> Alphabet | C11: =Plan!C27 -> Individual Stocks | D11: 0 | E11: 0 | F11: 0 | G11: =D11*F11 -> 0 | H11: =D11*E11 -> 0 | I11: =G11-H11 -> 0 | J11: =IF(H11>0,I11/H11,0) -> 0 | K11: =IF(G$17>0,G11/G$17,0) -> 0 | L11: =Plan!D27 -> 0.06 | M11: =IF(G$17>0,K11-L11,0) -> 0 | N11: =IF(G$17=0,"-",IF(ABS(M11)>Plan!$B$8,IF(M11>0,"Overweight","Underweight"),"OK")) -> - | O11: =MAX(0,L11*(G$17+Plan!$B$4)-G11) -> 90 | P11: =IF(O$17=0,L11*Plan!$B$4,O11/O$17*Plan!$B$4) -> 90 | Q11: =IF(F11>0,P11/F11,"enter price") -> enter price
A12: =IF(Plan!A28="","",Plan!A28) -> AMZN | B12: =Plan!B28 -> Amazon | C12: =Plan!C28 -> Individual Stocks | D12: 0 | E12: 0 | F12: 0 | G12: =D12*F12 -> 0 | H12: =D12*E12 -> 0 | I12: =G12-H12 -> 0 | J12: =IF(H12>0,I12/H12,0) -> 0 | K12: =IF(G$17>0,G12/G$17,0) -> 0 | L12: =Plan!D28 -> 0.06 | M12: =IF(G$17>0,K12-L12,0) -> 0 | N12: =IF(G$17=0,"-",IF(ABS(M12)>Plan!$B$8,IF(M12>0,"Overweight","Underweight"),"OK")) -> - | O12: =MAX(0,L12*(G$17+Plan!$B$4)-G12) -> 90 | P12: =IF(O$17=0,L12*Plan!$B$4,O12/O$17*Plan!$B$4) -> 90 | Q12: =IF(F12>0,P12/F12,"enter price") -> enter price
A13: =IF(Plan!A29="","",Plan!A29) -> BRK.B | B13: =Plan!B29 -> Berkshire Hathaway | C13: =Plan!C29 -> Individual Stocks | D13: 0 | E13: 0 | F13: 0 | G13: =D13*F13 -> 0 | H13: =D13*E13 -> 0 | I13: =G13-H13 -> 0 | J13: =IF(H13>0,I13/H13,0) -> 0 | K13: =IF(G$17>0,G13/G$17,0) -> 0 | L13: =Plan!D29 -> 0.06 | M13: =IF(G$17>0,K13-L13,0) -> 0 | N13: =IF(G$17=0,"-",IF(ABS(M13)>Plan!$B$8,IF(M13>0,"Overweight","Underweight"),"OK")) -> - | O13: =MAX(0,L13*(G$17+Plan!$B$4)-G13) -> 90 | P13: =IF(O$17=0,L13*Plan!$B$4,O13/O$17*Plan!$B$4) -> 90 | Q13: =IF(F13>0,P13/F13,"enter price") -> enter price
A14: =IF(Plan!A30="","",Plan!A30) -> BND | B14: =Plan!B30 -> Vanguard Total Bond Market ETF | C14: =Plan!C30 -> Bonds | D14: 0 | E14: 0 | F14: 0 | G14: =D14*F14 -> 0 | H14: =D14*E14 -> 0 | I14: =G14-H14 -> 0 | J14: =IF(H14>0,I14/H14,0) -> 0 | K14: =IF(G$17>0,G14/G$17,0) -> 0 | L14: =Plan!D30 -> 0.15 | M14: =IF(G$17>0,K14-L14,0) -> 0 | N14: =IF(G$17=0,"-",IF(ABS(M14)>Plan!$B$8,IF(M14>0,"Overweight","Underweight"),"OK")) -> - | O14: =MAX(0,L14*(G$17+Plan!$B$4)-G14) -> 225 | P14: =IF(O$17=0,L14*Plan!$B$4,O14/O$17*Plan!$B$4) -> 225 | Q14: =IF(F14>0,P14/F14,"enter price") -> enter price
A15: =IF(Plan!A31="","",Plan!A31) -> SGOV | B15: =Plan!B31 -> iShares 0-3 Month Treasury Bond ETF | C15: =Plan!C31 -> Cash / T-Bills | D15: 0 | E15: 0 | F15: 0 | G15: =D15*F15 -> 0 | H15: =D15*E15 -> 0 | I15: =G15-H15 -> 0 | J15: =IF(H15>0,I15/H15,0) -> 0 | K15: =IF(G$17>0,G15/G$17,0) -> 0 | L15: =Plan!D31 -> 0.05 | M15: =IF(G$17>0,K15-L15,0) -> 0 | N15: =IF(G$17=0,"-",IF(ABS(M15)>Plan!$B$8,IF(M15>0,"Overweight","Underweight"),"OK")) -> - | O15: =MAX(0,L15*(G$17+Plan!$B$4)-G15) -> 75 | P15: =IF(O$17=0,L15*Plan!$B$4,O15/O$17*Plan!$B$4) -> 75 | Q15: =IF(F15>0,P15/F15,"enter price") -> enter price
A16: =IF(Plan!A32="","",Plan!A32) | B16: =Plan!B32 -> (spare slot) | C16: =Plan!C32 -> Individual Stocks | D16: 0 | E16: 0 | F16: 0 | G16: =D16*F16 -> 0 | H16: =D16*E16 -> 0 | I16: =G16-H16 -> 0 | J16: =IF(H16>0,I16/H16,0) -> 0 | K16: =IF(G$17>0,G16/G$17,0) -> 0 | L16: =Plan!D32 -> 0 | M16: =IF(G$17>0,K16-L16,0) -> 0 | N16: =IF(G$17=0,"-",IF(ABS(M16)>Plan!$B$8,IF(M16>0,"Overweight","Underweight"),"OK")) -> - | O16: =MAX(0,L16*(G$17+Plan!$B$4)-G16) -> 0 | P16: =IF(O$17=0,L16*Plan!$B$4,O16/O$17*Plan!$B$4) -> 0 | Q16: =IF(F16>0,P16/F16,"enter price") -> enter price
A17: Total | G17: =SUM(G6:G16) -> 0 | H17: =SUM(H6:H16) -> 0 | I17: =SUM(I6:I16) -> 0 | J17: =IF(H17>0,I17/H17,0) -> 0 | K17: =SUM(K6:K16) -> 0 | L17: =SUM(L6:L16) -> 1 | O17: =SUM(O6:O16) -> 1500 | P17: =SUM(P6:P16) -> 1500
A19: How the buy plan works: each holding's gap = target % x (portfolio + this month's contribution) - current value. The contribution is split in proportion to the gaps, so underweight positions get more. Fractional shares are supported on Robinhood.

Sheet Projection
A1: 30-Year Projection
A2: Contributions are assumed spread evenly through each year. Returns are assumptions, not guarantees; real markets are far bumpier than a smooth line.
A4: Year | B4: Contribution | C4: Base case | D4: Low case | E4: High case | F4: Total contributed | G4: Base, today's dollars | H4: Base gain over contributed
A5: 0 | C5: =Plan!$B$5 -> 0 | D5: =Plan!$B$5 -> 0 | E5: =Plan!$B$5 -> 0 | F5: =Plan!$B$5 -> 0 | G5: =C5 -> 0 | H5: =C5-F5 -> 0
A6: 1 | B6: =Plan!$B$4*12*(1+Plan!$B$6)^(A6-1) -> 18000 | C6: =C5*(1+Plan!$E$33)+B6*(1+Plan!$E$33/2) -> 18593.1 | D6: =D5*(1+Plan!$E$33-Plan!$B$9)+B6*(1+(Plan!$E$33-Plan!$B$9)/2) -> 18413.1 | E6: =E5*(1+Plan!$E$33+Plan!$B$9)+B6*(1+(Plan!$E$33+Plan!$B$9)/2) -> 18773.1 | F6: =F5+B6 -> 18000 | G6: =C6/(1+Plan!$B$7)^A6 -> 18139.61 | H6: =C6-F6 -> 593.1
A7: 2 | B7: =Plan!$B$4*12*(1+Plan!$B$6)^(A7-1) -> 18540 | C7: =C6*(1+Plan!$E$33)+B7*(1+Plan!$E$33/2) -> 38969.278 | D7: =D6*(1+Plan!$E$33-Plan!$B$9)+B7*(1+(Plan!$E$33-Plan!$B$9)/2) -> 38223.754 | E7: =E6*(1+Plan!$E$33+Plan!$B$9)+B7*(1+(Plan!$E$33+Plan!$B$9)/2) -> 39722.002 | F7: =F6+B7 -> 36540 | G7: =C7/(1+Plan!$B$7)^A7 -> 37091.52 | H7: =C7-F7 -> 2429.2783
A8: 3 | B8: =Plan!$B$4*12*(1+Plan!$B$6)^(A8-1) -> 19096.2 | C8: =C7*(1+Plan!$E$33)+B8*(1+Plan!$E$33/2) -> 61262.774 | D8: =D7*(1+Plan!$E$33-Plan!$B$9)+B8*(1+(Plan!$E$33-Plan!$B$9)/2) -> 59512.682 | E8: =E7*(1+Plan!$E$33+Plan!$B$9)+B8*(1+(Plan!$E$33+Plan!$B$9)/2) -> 63050.504 | F8: =F7+B8 -> 55636.2 | G8: =C8/(1+Plan!$B$7)^A8 -> 56888.575 | H8: =C8-F8 -> 5626.5735
A9: 4 | B9: =Plan!$B$4*12*(1+Plan!$B$6)^(A9-1) -> 19669.086 | C9: =C8*(1+Plan!$E$33)+B9*(1+Plan!$E$33/2) -> 85617.173 | D9: =D8*(1+Plan!$E$33-Plan!$B$9)+B9*(1+(Plan!$E$33-Plan!$B$9)/2) -> 82364.806 | E9: =E8*(1+Plan!$E$33+Plan!$B$9)+B9*(1+(Plan!$E$33+Plan!$B$9)/2) -> 88980.416 | F9: =F8+B9 -> 75305.286 | G9: =C9/(1+Plan!$B$7)^A9 -> 77564.933 | H9: =C9-F9 -> 10311.887
A10: 5 | B10: =Plan!$B$4*12*(1+Plan!$B$6)^(A10-1) -> 20259.159 | C10: =C9*(1+Plan!$E$33)+B10*(1+Plan!$E$33/2) -> 112186.04 | D10: =D9*(1+Plan!$E$33-Plan!$B$9)+B10*(1+(Plan!$E$33-Plan!$B$9)/2) -> 106869.46 | E10: =E9*(1+Plan!$E$33+Plan!$B$9)+B10*(1+(Plan!$E$33+Plan!$B$9)/2) -> 117753.12 | F10: =F9+B10 -> 95564.445 | G10: =C10/(1+Plan!$B$7)^A10 -> 99156.114 | H10: =C10-F10 -> 16621.598
A11: 6 | B11: =Plan!$B$4*12*(1+Plan!$B$6)^(A11-1) -> 20866.933 | C11: =C10*(1+Plan!$E$33)+B11*(1+Plan!$E$33/2) -> 141133.6 | D11: =D10*(1+Plan!$E$33-Plan!$B$9)+B11*(1+(Plan!$E$33-Plan!$B$9)/2) -> 133120.59 | E11: =E10*(1+Plan!$E$33+Plan!$B$9)+B11*(1+(Plan!$E$33+Plan!$B$9)/2) -> 149631.28 | F11: =F10+B11 -> 116431.38 | G11: =C11/(1+Plan!$B$7)^A11 -> 121699.06 | H11: =C11-F11 -> 24702.223
A12: 7 | B12: =Plan!$B$4*12*(1+Plan!$B$6)^(A12-1) -> 21492.941 | C12: =C11*(1+Plan!$E$33)+B12*(1+Plan!$E$33/2) -> 172635.44 | D12: =D11*(1+Plan!$E$33-Plan!$B$9)+B12*(1+(Plan!$E$33-Plan!$B$9)/2) -> 161217.03 | E12: =E11*(1+Plan!$E$33+Plan!$B$9)+B12*(1+(Plan!$E$33+Plan!$B$9)/2) -> 184900.67 | F12: =F11+B12 -> 137924.32 | G12: =C12/(1+Plan!$B$7)^A12 -> 145232.19 | H12: =C12-F12 -> 34711.12
A13: 8 | B13: =Plan!$B$4*12*(1+Plan!$B$6)^(A13-1) -> 22137.73 | C13: =C12*(1+Plan!$E$33)+B13*(1+Plan!$E$33/2) -> 206879.28 | D13: =D12*(1+Plan!$E$33-Plan!$B$9)+B13*(1+(Plan!$E$33-Plan!$B$9)/2) -> 191262.69 | E13: =E12*(1+Plan!$E$33+Plan!$B$9)+B13*(1+(Plan!$E$33+Plan!$B$9)/2) -> 223872.19 | F13: =F12+B13 -> 160062.05 | G13: =C13/(1+Plan!$B$7)^A13 -> 169795.46 | H13: =C13-F13 -> 46817.234
A14: 9 | B14: =Plan!$B$4*12*(1+Plan!$B$6)^(A14-1) -> 22801.861 | C14: =C13*(1+Plan!$E$33)+B14*(1+Plan!$E$33/2) -> 244065.81 | D14: =D13*(1+Plan!$E$33-Plan!$B$9)+B14*(1+(Plan!$E$33-Plan!$B$9)/2) -> 223366.81 | E14: =E13*(1+Plan!$E$33+Plan!$B$9)+B14*(1+(Plan!$E$33+Plan!$B$9)/2) -> 266884.01 | F14: =F13+B14 -> 182863.91 | G14: =C14/(1+Plan!$B$7)^A14 -> 195430.42 | H14: =C14-F14 -> 61201.9
A15: 10 | B15: =Plan!$B$4*12*(1+Plan!$B$6)^(A15-1) -> 23485.917 | C15: =C14*(1+Plan!$E$33)+B15*(1+Plan!$E$33/2) -> 284409.53 | D15: =D14*(1+Plan!$E$33-Plan!$B$9)+B15*(1+(Plan!$E$33-Plan!$B$9)/2) -> 257644.26 | E15: =E14*(1+Plan!$E$33+Plan!$B$9)+B15*(1+(Plan!$E$33+Plan!$B$9)/2) -> 314303.98 | F15: =F14+B15 -> 206349.83 | G15: =C15/(1+Plan!$B$7)^A15 -> 222180.27 | H15: =C15-F15 -> 78059.698
A16: 11 | B16: =Plan!$B$4*12*(1+Plan!$B$6)^(A16-1) -> 24190.495 | C16: =C15*(1+Plan!$E$33)+B16*(1+Plan!$E$33/2) -> 328139.68 | D16: =D15*(1+Plan!$E$33-Plan!$B$9)+B16*(1+(Plan!$E$33-Plan!$B$9)/2) -> 294215.8 | E16: =E15*(1+Plan!$E$33+Plan!$B$9)+B16*(1+(Plan!$E$33+Plan!$B$9)/2) -> 366532.17 | F16: =F15+B16 -> 230540.32 | G16: =C16/(1+Plan!$B$7)^A16 -> 250089.95 | H16: =C16-F16 -> 97599.362
A17: 12 | B17: =Plan!$B$4*12*(1+Plan!$B$6)^(A17-1) -> 24916.21 | C17: =C16*(1+Plan!$E$33)+B17*(1+Plan!$E$33/2) -> 375501.29 | D17: =D16*(1+Plan!$E$33-Plan!$B$9)+B17*(1+(Plan!$E$33-Plan!$B$9)/2) -> 333208.34 | E17: =E16*(1+Plan!$E$33+Plan!$B$9)+B17*(1+(Plan!$E$33+Plan!$B$9)/2) -> 424003.65 | F17: =F16+B17 -> 255456.53 | G17: =C17/(1+Plan!$B$7)^A17 -> 279206.19 | H17: =C17-F17 -> 120044.76
... A35: 30 | B35: =Plan!$B$4*12*(1+Plan!$B$6)^(A35-1) -> 42418.179 | C35: =C34*(1+Plan!$E$33)+B35*(1+Plan!$E$33/2) -> 2256478.8 | D35: =D34*(1+Plan!$E$33-Plan!$B$9)+B35*(1+(Plan!$E$33-Plan!$B$9)/2) -> 1639857.8 | E35: =E34*(1+Plan!$E$33+Plan!$B$9)+B35*(1+(Plan!$E$33+Plan!$B$9)/2) -> 3164258.1 | F35: =F34+B35 -> 856357.48 | G35: =C35/(1+Plan!$B$7)^A35 -> 1075759.7 | H35: =C35-F35 -> 1400121.3

Sheet Notes
A1: How to Use & Notes
A3: HOW TO USE
A4: 1. Plan sheet: set your monthly amount (yellow) and review the target weights. Weights must total 100%.
A5: 2. Holdings sheet: type shares, average cost and price from Robinhood into the yellow cells. Leave at 0 if you are starting fresh.
A6: 3. Each month: open Holdings and use the "Buy this month" column. It steers new money to underweight positions so you rebalance without selling (no taxable sales).
A7: 4. Re-check the Status column quarterly; a holding drifting past your tolerance is a signal to tilt future buys, not to panic-sell.
A9: DESIGN NOTES
A10: - Moderate growth: about 80% stocks / 20% bonds and T-bills. Within stocks, ~50% broad ETFs, ~30% individual large caps, ~5% dividend ETF.
A11: - Individual stocks total 30% (6% each). Keeping any single stock around 5-6% limits the damage if one thesis breaks.
A12: - The tickers are an illustrative example of a diversified mix, not a recommendation. Swap them in the Plan sheet; asset-class return assumptions update automatically.
A13: - Fees: broad index ETFs listed here have very low expense ratios; check each fund's current expense ratio and holdings before buying.
A14: - Consider holding long-term money in a tax-advantaged account (Roth/Traditional IRA) if eligible; check current IRS contribution limits and Robinhood's available account types.
... A16: - Educational template, not financial advice. A fee-only fiduciary advisor can tailor this to your taxes and goals.
