Workbook

Sheet Summary
A1: NVIDIA (NVDA) - Valuation & Stock Pitch
A2: ="Based on FY2024-FY2026 and 1H FY2027 financial statements | $ in millions except per share | Valuation date: "&TEXT(Assumptions!B4,"d-mmm-yyyy") -> Based on FY2024-FY2026 and 1H FY2027 financial statements | $ in millions except per share | Valuation date: 1-Oct-2026
A4: RECOMMENDATION | B4: =IF(B7>=Assumptions!B34,"BUY",IF(B7<=Assumptions!B35,"SELL","HOLD")) -> HOLD | D4: ="Rule: BUY if upside >= "&TEXT(Assumptions!B34,"0%")&"; SELL if <= "&TEXT(Assumptions!B35,"0%")&"; otherwise HOLD." -> Rule: BUY if upside >= 15%; SELL if <= -10%; otherwise HOLD.
A5: Current share price ($) | B5: =Assumptions!B5 -> 228.38
A6: Probability-weighted fair value ($) | B6: =E17 -> 237.92385
A7: Upside / (downside) to fair value | B7: =B6/B5-1 -> 0.041789339
A8: 12-month price target ($) | B8: =B6*(1+Assumptions!B23) -> 261.53779
A9: Base-case DCF value ($) | B9: =DCF!C15 -> 231.87761
A10: WACC / Base terminal growth | B10: =Assumptions!B27 -> 0.098894363 | C10: =Assumptions!C52 -> 0.035
A12: Scenario analysis
A13: Scenario | B13: Probability | C13: DCF value ($) | D13: P/E value ($) | E13: Blended fair value ($) | F13: Upside vs. price | G13: FY2028E EPS ($) | H13: FY2031E revenue
A14: Bear | B14: =Assumptions!B41 -> 0.25 | C14: =DCF!B15 -> 111.17101 | D14: =Valuation!B22 -> 118.15944 | E14: =Assumptions!$B$36*C14+(1-Assumptions!$B$36)*D14 -> 114.66522 | F14: =E14/Assumptions!$B$5-1 -> -0.49791916 | G14: =Projections!D23 -> 9.2776257 | H14: =Projections!G8 -> 450828.34
A15: Base | B15: =Assumptions!C41 -> 0.5 | C15: =DCF!C15 -> 231.87761 | D15: =Valuation!C22 -> 247.6727 | E15: =Assumptions!$B$36*C15+(1-Assumptions!$B$36)*D15 -> 239.77515 | F15: =E15/Assumptions!$B$5-1 -> 0.049895572 | G15: =Projections!D44 -> 12.375191 | H15: =Projections!G29 -> 795506.47
A16: Bull | B16: =Assumptions!D41 -> 0.25 | C16: =DCF!D15 -> 342.58533 | D16: =Valuation!D22 -> 372.37441 | E16: =Assumptions!$B$36*C16+(1-Assumptions!$B$36)*D16 -> 357.47987 | F16: =E16/Assumptions!$B$5-1 -> 0.56528537 | G16: =Projections!D65 -> 14.61902 | H16: =Projections!G50 -> 1079606.4
A17: Probability-weighted | B17: =SUM(B14:B16) -> 1 | C17: =SUMPRODUCT($B$14:$B$16,C14:C16) -> 229.37789 | D17: =SUMPRODUCT($B$14:$B$16,D14:D16) -> 246.46981 | E17: =SUMPRODUCT($B$14:$B$16,E14:E16) -> 237.92385 | F17: =E17/Assumptions!$B$5-1 -> 0.041789339 | G17: =SUMPRODUCT($B$14:$B$16,G14:G16) -> 12.161757 | H17: =SUMPRODUCT($B$14:$B$16,H14:H16) -> 780361.92
A19: Key metrics
A20: TTM revenue ($mm) | B20: =Historical!G5 -> 302970
A21: TTM GAAP operating margin | B21: =Valuation!B12 -> 0.65214048
A22: Q2 FY27 revenue growth (y/y) | B22: =Historical!I5/46743-1 -> 1.0585114 | C22: Q2 FY26 revenue $46,743mm (8-K)
A23: Q2 FY27 gross margin | B23: =Historical!I15 -> 0.74975317
A24: P/E (TTM, GAAP) | B24: =Valuation!B9 -> 28.725108
A25: P/E on FY2028E EPS (Base) | B25: =Valuation!B14 -> 18.454664
A26: Market cap ($mm) | B26: =Assumptions!B7 -> 5540498.8
A27: Base FY2027E revenue ($mm) | B27: =Projections!C29 -> 405963.44
A29: Investment thesis, risks & conclusion
A30: GROWTH: Q2 FY27 revenue of $96.2bn (+106% y/y), Data Center $89.0bn; Q3 guided to $108bn +/-2% with no China Data Center compute assumed.
A31: PROFITABILITY: GAAP gross margin 75.0% and operating margin ~66% in Q2 FY27 - elite for hardware; Q3 gross margin guided ~74%.
A32: BALANCE SHEET / CAPITAL RETURN: $56.6bn cash and debt securities, $25bn notes issued in Q2, ~$26bn returned in Q2, $99bn buyback authorization remaining.
A33: RISK - CASH CONVERSION: Q2 FCF fell to $21.3bn from $48.6bn as receivables rose $22bn (DSO 60 days vs. 45) and inventory rose ahead of Vera Rubin.
A34: RISK - CIRCULARITY & CONCENTRATION: ~$94bn of equity stakes (marketable + non-marketable) in the AI ecosystem; large customers on extended payment terms.
A35: RISK - CYCLE & VALUATION: results hinge on hyperscaler capex, custom-silicon competition and export controls; value is highly sensitive to WACC / terminal growth (see DCF sheet).
A36: ="CONCLUSION: Model output is "&B4&" - probability-weighted fair value of "&TEXT(B6,"$#,##0")&" vs. price of "&TEXT(B5,"$#,##0.00")&" ("&TEXT(B7,"+0.0%;-0.0%")&"); Base-case DCF "&TEXT(B9,"$#,##0")&"." -> CONCLUSION: Model output is HOLD - probability-weighted fair value of $238 vs. price of $228.38 (+4.2%); Base-case DCF $232.
A37: Educational analysis built from public filings and clearly labelled assumptions - not investment advice. Flex the yellow cells on the Assumptions sheet.
A39: Chart data: value per share vs. current price ($)
A40: Current price | B40: =B5 -> 228.38
A41: Bear | B41: =E14 -> 114.66522
A42: Base | B42: =E15 -> 239.77515
A43: Bull | B43: =E16 -> 357.47987
A44: Prob-weighted | B44: =E17 -> 237.92385

Sheet Assumptions
A1: Assumptions & Inputs
A2: Blue = hard-coded input | Black = formula | Green = link to another sheet | Yellow fill = key assumption to flex. $ in millions except per share.
A3: Market data & balance sheet (as of Q2 FY27, quarter ended 26-Jul-2026)
A4: Valuation date | B4: 46296 | E4: Analysis date
A5: Current share price ($) | B5: 228.38 | E5: Close on 30-Sep-2026 (previous close per Yahoo Finance / Motley Fool quote, 1-Oct-2026). Update to refresh.
A6: Diluted shares outstanding (mm) | B6: 24260 | E6: Derived: Q2 FY27 GAAP net income $59,688mm / GAAP diluted EPS $2.46 (NVIDIA Q2 FY27 8-K). Basic ~24.1bn per market-data sites.
A7: Market capitalization | B7: =B5*B6 -> 5540498.8 | E7: Price x diluted shares
A8: Cash & cash equivalents | B8: 22443 | E8: Q2 FY27 balance sheet
A9: Marketable debt securities | B9: 34143 | E9: Q2 FY27 balance sheet
A10: Marketable equity securities | B10: 42783 | E10: Q2 FY27 balance sheet (strategic stakes, up from $12,886mm at FY26 year-end)
A11: Non-marketable securities | B11: 51157 | E11: Q2 FY27 balance sheet (private stakes, up from $22,251mm at FY26 year-end)
A12: Value credited: marketable equity (% of book) | B12: 1 | E12: ASSUMPTION: full credit at market value
A13: Value credited: non-marketable securities (% of book) | B13: 0.5 | E13: ASSUMPTION: 50% haircut - illiquid, partly stakes in NVIDIA customers/ecosystem
A14: Short-term debt | B14: 1000 | E14: Q2 FY27 balance sheet
A15: Long-term debt | B15: 32366 | E15: Q2 FY27 balance sheet (incl. $25.0bn senior notes issued in Q2 FY27)
A16: Net cash & investments (adjusted) | B16: =B8+B9+B10*B12+B11*B13-B14-B15 -> 91581.5 | E16: Cash + debt securities + credited equity stakes - debt
A17: Enterprise value | B17: =B7-B16 -> 5448917.3 | E17: Market cap - adjusted net cash
A19: Cost of capital
A20: Risk-free rate (10-yr UST) | B20: 0.043 | E20: ASSUMPTION: approx. 10-yr Treasury yield; verify against current curve
A21: Equity risk premium | B21: 0.045 | E21: ASSUMPTION
A22: Beta | B22: 1.25 | E22: ASSUMPTION: below 60-mo regression beta of 2.22 (Yahoo/Barchart), which reflects hyper-growth period; flex via DCF sensitivity
A23: Cost of equity (CAPM) | B23: =B20+B22*B21 -> 0.09925 | E23: Rf + Beta x ERP
A24: Pre-tax cost of debt | B24: 0.048 | E24: ASSUMPTION: approx. yield on recent investment-grade notes
A25: Tax rate | B25: 0.17 | E25: NVIDIA FY27 guidance: 16%-18% (Q2 FY27 press release)
A26: Debt weight D/(D+E) | B26: =(B14+B15)/(B14+B15+B7) -> 0.0059861517 | E26: Market-value weights
A27: WACC | B27: =(1-B26)*B23+B26*B24*(1-B25) -> 0.098894363 | E27: Discount rate used in DCF
A29: Operating & decision-rule assumptions (all scenarios)
A30: D&A (% of revenue) | B30: 0.012 | E30: ASSUMPTION: asset-light model; D&A is small vs. revenue
A31: Capex (% of revenue) | B31: 0.018 | E31: ASSUMPTION: Q1 FY27 capex ~$1.8bn on $81.6bn revenue (~2.2%); trending lower as revenue scales
A32: Working-capital investment (% of change in revenue) | B32: 0.12 | E32: ASSUMPTION: Q2 FY27 receivables +$22.3bn and inventory +$5.8bn on a $14.6bn revenue increase - heavy build; 12% blended through cycle
A33: 1H FY27 actual free cash flow (already in cash) | B33: 69895 | E33: Q1 $48,554mm + Q2 $21,341mm (company-defined FCF). Removed from FY27E so only 2H FY27 is discounted.
A34: BUY if upside to fair value >= | B34: 0.15 | E34: ASSUMPTION: decision rule
A35: SELL if upside to fair value <= | B35: -0.1 | E35: ASSUMPTION: decision rule; in between = HOLD
A36: Weight on DCF in blended fair value | B36: 0.5 | E36: Remainder weighted to forward P/E value (discounted to today at cost of equity)
A39: Scenario drivers
A40: Driver | B40: Bear | C40: Base | D40: Bull | E40: Rationale
A41: Probability | B41: 0.25 | C41: 0.5 | D41: 0.25 | E41: Must sum to 100% (check in column F) | F41: =IF(ABS(SUM(B41:D41)-1)<0.0001,"OK","CHECK: not 100%") -> OK
A42: Revenue growth FY2027E | B42: 0.82 | C42: 0.88 | D42: 0.94 | E42: 1H FY27 revenue $177.8bn + Q3 guide $108.0bn +/-2% + Q4 est. => ~$405bn base (+88%)
A43: Revenue growth FY2028E | B43: 0.15 | C43: 0.35 | D43: 0.5 | E43: Vera Rubin ramp vs. hyperscaler capex digestion
A44: Revenue growth FY2029E | B44: 0.05 | C44: 0.2 | D44: 0.3 | E44: Law of large numbers; competition (custom ASICs, AMD)
...

Sheet Historical
A1: Historical Financials (GAAP)
A2: $ in millions except per share. FY ends late January (FY2026 = year ended 25-Jan-2026). Blue = from filings; black = formula; "n/a" = not sourced.
B4: FY2024 | C4: FY2025 | D4: FY2026 | E4: 1H FY26 | F4: 1H FY27 | G4: TTM (Jul-26) | H4: Q1 FY27 | I4: Q2 FY27 | J4: Source / note
A5: Revenue | B5: 60922 | C5: 130497 | D5: 215938 | E5: 90805 | F5: 177837 | G5: =D5-E5+F5 -> 302970 | H5: 81615 | I5: 96221 | J5: FY24 per 10-K; FY25-FY26, 1H and quarters per NVIDIA 8-Ks (Feb-26, Aug-26)
A6: Data Center revenue | B6: n/a | C6: 115186 | D6: 193700 | E6: n/a | F6: n/a | G6: n/a | H6: n/a | I6: 89020 | J6: FY26 per company press release (+68% y/y); Q2 FY27 $89.0bn
A7: Gross profit | B7: 44301 | C7: 97858 | D7: 153463 | E7: 60521 | F7: 133299 | G7: =D7-E7+F7 -> 226241 | H7: 61156 | I7: 72142 | J7: 1H FY27/Q1/Q2 derived: revenue - cost of revenue ($44,538mm 1H; $24,079mm Q2)
A8: Operating income | B8: 32972 | C8: 81453 | D8: 130387 | E8: 50078 | F8: 117270 | G8: =D8-E8+F8 -> 197579 | H8: 53536 | I8: 63734 | J8: Q1 FY27 derived = 1H - Q2
A9: Net income | B9: 29760 | C9: 72880 | D9: 120067 | E9: 45197 | F9: 118010 | G9: =D9-E9+F9 -> 192880 | H9: 58321 | I9: 59688 | J9: Includes gains on equity securities (other income $24.1bn in 1H FY27)
A10: Diluted EPS ($) | B10: 1.19 | C10: 2.94 | D10: 4.9 | E10: n/a | F10: n/a | G10: =G9/Assumptions!B6 -> 7.9505359 | H10: n/a | I10: 2.46 | J10: TTM EPS approximated using current diluted shares
A11: Free cash flow (company-defined) | B11: 27021 | C11: 60853 | D11: n/a | E11: 39584 | F11: 69895 | G11: n/a | H11: 48554 | I11: 21341 | J11: OCF less capex & principal payments; FY26 total not sourced
A13: Growth & margins
A14: Revenue growth (y/y) | C14: =C5/B5-1 -> 1.1420341 | D14: =D5/C5-1 -> 0.65473536 | F14: =F5/E5-1 -> 0.95844942
A15: Gross margin | B15: =B7/B5 -> 0.72717573 | C15: =C7/C5 -> 0.74988697 | D15: =D7/D5 -> 0.71068084 | E15: =E7/E5 -> 0.66649414 | F15: =F7/F5 -> 0.74955718 | G15: =G7/G5 -> 0.7467439 | H15: =H7/H5 -> 0.74932304 | I15: =I7/I5 -> 0.74975317
A16: Operating margin | B16: =B8/B5 -> 0.54121664 | C16: =C8/C5 -> 0.62417527 | D16: =D8/D5 -> 0.60381684 | E16: =E8/E5 -> 0.55148946 | F16: =F8/F5 -> 0.65942408 | G16: =G8/G5 -> 0.65214048 | H16: =H8/H5 -> 0.65595785 | I16: =I8/I5 -> 0.662371
A17: Net margin | B17: =B9/B5 -> 0.48849348 | C17: =C9/C5 -> 0.55848027 | D17: =D9/D5 -> 0.55602534 | E17: =E9/E5 -> 0.49773691 | F17: =F9/F5 -> 0.66358519 | G17: =G9/G5 -> 0.63663069 | H17: =H9/H5 -> 0.71458678 | I17: =I9/I5 -> 0.62032197
A18: FCF margin | B18: =B11/B5 -> 0.44353436 | C18: =C11/C5 -> 0.46631723 | E18: =E11/E5 -> 0.43592313 | F18: =F11/F5 -> 0.39302845 | H18: =H11/H5 -> 0.59491515 | I18: =I11/I5 -> 0.2217915
A19: Data Center % of revenue | C19: =C6/C5 -> 0.88267163 | D19: =D6/D5 -> 0.89701674 | I19: =I6/I5 -> 0.92516187
A20: Operating income growth (y/y) | C20: =C8/B8-1 -> 1.4703688 | D20: =D8/C8-1 -> 0.60076363 | F20: =F8/E8-1 -> 1.3417469
A21: Net income growth (y/y) | C21: =C9/B9-1 -> 1.4489247 | D21: =D9/C9-1 -> 0.64746158 | F21: =F9/E9-1 -> 1.611014
A23: Revenue 2-yr CAGR (FY24-FY26) | D23: =(D5/B5)^(1/2)-1 -> 0.88268413

Sheet Projections
A1: Projections - Unlevered Free Cash Flow by Scenario
A2: $ in millions. FY2027E-FY2031E. FY2027E is a full year; the 1H actual FCF is removed in the "FCF to discount" row so only 2H FY27 is valued. EPS ignores other income (conservative).
A4: BEAR CASE
A5: Fiscal year | B5: FY2026A | C5: FY2027E | D5: FY2028E | E5: FY2029E | F5: FY2030E | G5: FY2031E
A6: Period end date | C6: 46418 | D6: 46783 | E6: 47149 | F6: 47514 | G6: 47879
A7: Revenue growth | C7: =Assumptions!B42 -> 0.82 | D7: =Assumptions!B43 -> 0.15 | E7: =Assumptions!B44 -> 0.05 | F7: =Assumptions!B45 -> 0 | G7: =Assumptions!B46 -> -0.05
A8: Revenue | B8: =Historical!D5 -> 215938 | C8: =B8*(1+C7) -> 393007.16 | D8: =C8*(1+D7) -> 451958.23 | E8: =D8*(1+E7) -> 474556.15 | F8: =E8*(1+F7) -> 474556.15 | G8: =F8*(1+G7) -> 450828.34
A9: Operating margin | B9: =Historical!D16 -> 0.60381684 | C9: =Assumptions!B47 -> 0.64 | D9: =Assumptions!B48 -> 0.6 | E9: =Assumptions!B49 -> 0.56 | F9: =Assumptions!B50 -> 0.52 | G9: =Assumptions!B51 -> 0.5
A10: Operating income (EBIT) | B10: =Historical!D8 -> 130387 | C10: =C8*C9 -> 251524.58 | D10: =D8*D9 -> 271174.94 | E10: =E8*E9 -> 265751.44 | F10: =F8*F9 -> 246769.2 | G10: =G8*G9 -> 225414.17
A11: Less: taxes on EBIT | C11: =-C10*Assumptions!$B$25 -> -42759.179 | D11: =-D10*Assumptions!$B$25 -> -46099.74 | E11: =-E10*Assumptions!$B$25 -> -45177.745 | F11: =-F10*Assumptions!$B$25 -> -41950.763 | G11: =-G10*Assumptions!$B$25 -> -38320.409
A12: NOPAT | C12: =C10+C11 -> 208765.4 | D12: =D10+D11 -> 225075.2 | E12: =E10+E11 -> 220573.7 | F12: =F10+F11 -> 204818.43 | G12: =G10+G11 -> 187093.76
A13: Plus: D&A | C13: =C8*Assumptions!$B$30 -> 4716.0859 | D13: =D8*Assumptions!$B$30 -> 5423.4988 | E13: =E8*Assumptions!$B$30 -> 5694.6737 | F13: =F8*Assumptions!$B$30 -> 5694.6737 | G13: =G8*Assumptions!$B$30 -> 5409.9401
A14: Less: capex | C14: =-C8*Assumptions!$B$31 -> -7074.1289 | D14: =-D8*Assumptions!$B$31 -> -8135.2482 | E14: =-E8*Assumptions!$B$31 -> -8542.0106 | F14: =-F8*Assumptions!$B$31 -> -8542.0106 | G14: =-G8*Assumptions!$B$31 -> -8114.9101
A15: Less: increase in working capital | C15: =-(C8-B8)*Assumptions!$B$32 -> -21248.299 | D15: =-(D8-C8)*Assumptions!$B$32 -> -7074.1289 | E15: =-(E8-D8)*Assumptions!$B$32 -> -2711.7494 | F15: =-(F8-E8)*Assumptions!$B$32 -> 0 | G15: =-(G8-F8)*Assumptions!$B$32 -> 2847.3369
A16: Unlevered free cash flow | C16: =C12+C13+C14+C15 -> 185159.06 | D16: =D12+D13+D14+D15 -> 215289.32 | E16: =E12+E13+E14+E15 -> 215014.61 | F16: =F12+F13+F14+F15 -> 201971.1 | G16: =G12+G13+G14+G15 -> 187236.13
A17: Less: 1H FY27 actual FCF (already realized) | C17: =-Assumptions!$B$33 -> -69895 | D17: 0 | E17: 0 | F17: 0 | G17: 0
A18: FCF to discount | C18: =C16+C17 -> 115264.06 | D18: =D16+D17 -> 215289.32 | E18: =E16+E17 -> 215014.61 | F18: =F16+F17 -> 201971.1 | G18: =G16+G17 -> 187236.13
A19: Discount period (years) | C19: =(C6-Assumptions!$B$4)/365 -> 0.33424658 | D19: =(D6-Assumptions!$B$4)/365 -> 1.3342466 | E19: =(E6-Assumptions!$B$4)/365 -> 2.3369863 | F19: =(F6-Assumptions!$B$4)/365 -> 3.3369863 | G19: =(G6-Assumptions!$B$4)/365 -> 4.3369863
A20: Discount factor | C20: =1/(1+Assumptions!$B$27)^C19 -> 0.96897063 | D20: =1/(1+Assumptions!$B$27)^D19 -> 0.88176868 | E20: =1/(1+Assumptions!$B$27)^E19 -> 0.80220713 | F20: =1/(1+Assumptions!$B$27)^F19 -> 0.73001296 | G20: =1/(1+Assumptions!$B$27)^G19 -> 0.66431587
A21: PV of FCF | C21: =C18*C20 -> 111687.49 | D21: =D18*D20 -> 189835.38 | E21: =E18*E20 -> 172486.25 | F21: =F18*F20 -> 147441.52 | G21: =G18*G20 -> 124383.93
A22: Net income (EBIT x (1-t)) | C22: =C10*(1-Assumptions!$B$25) -> 208765.4 | D22: =D10*(1-Assumptions!$B$25) -> 225075.2 | E22: =E10*(1-Assumptions!$B$25) -> 220573.7 | F22: =F10*(1-Assumptions!$B$25) -> 204818.43 | G22: =G10*(1-Assumptions!$B$25) -> 187093.76
A23: Diluted EPS ($) | C23: =C22/Assumptions!$B$6 -> 8.605334 | D23: =D22/Assumptions!$B$6 -> 9.2776257 | E23: =E22/Assumptions!$B$6 -> 9.0920732 | F23: =F22/Assumptions!$B$6 -> 8.4426394 | G23: =G22/Assumptions!$B$6 -> 7.7120264
A25: BASE CASE
A26: Fiscal year | B26: FY2026A | C26: FY2027E | D26: FY2028E | E26: FY2029E | F26: FY2030E | G26: FY2031E
A27: Period end date | C27: 46418 | D27: 46783 | E27: 47149 | F27: 47514 | G27: 47879
A28: Revenue growth | C28: =Assumptions!C42 -> 0.88 | D28: =Assumptions!C43 -> 0.35 | E28: =Assumptions!C44 -> 0.2 | F28: =Assumptions!C45 -> 0.12 | G28: =Assumptions!C46 -> 0.08
A29: Revenue | B29: =Historical!D5 -> 215938 | C29: =B29*(1+C28) -> 405963.44 | D29: =C29*(1+D28) -> 548050.64 | E29: =D29*(1+E28) -> 657660.77 | F29: =E29*(1+F28) -> 736580.07 | G29: =F29*(1+G28) -> 795506.47
A30: Operating margin | B30: =Historical!D16 -> 0.60381684 | C30: =Assumptions!C47 -> 0.66 | D30: =Assumptions!C48 -> 0.66 | E30: =Assumptions!C49 -> 0.65 | F30: =Assumptions!C50 -> 0.64 | G30: =Assumptions!C51 -> 0.63
A31: Operating income (EBIT) | B31: =Historical!D8 -> 130387 | C31: =C29*C30 -> 267935.87 | D31: =D29*D30 -> 361713.43 | E31: =E29*E30 -> 427479.5 | F31: =F29*F30 -> 471411.24 | G31: =G29*G30 -> 501169.08
A32: Less: taxes on EBIT | C32: =-C31*Assumptions!$B$25 -> -45549.098 | D32: =-D31*Assumptions!$B$25 -> -61491.282 | E32: =-E31*Assumptions!$B$25 -> -72671.515 | F32: =-F31*Assumptions!$B$25 -> -80139.911 | G32: =-G31*Assumptions!$B$25 -> -85198.743
A33: NOPAT | C33: =C31+C32 -> 222386.77 | D33: =D31+D32 -> 300222.14 | E33: =E31+E32 -> 354807.99 | F33: =F31+F32 -> 391271.33 | G33: =G31+G32 -> 415970.33
A34: Plus: D&A | C34: =C29*Assumptions!$B$30 -> 4871.5613 | D34: =D29*Assumptions!$B$30 -> 6576.6077 | E34: =E29*Assumptions!$B$30 -> 7891.9293 | F34: =F29*Assumptions!$B$30 -> 8838.9608 | G34: =G29*Assumptions!$B$30 -> 9546.0776
A35: Less: capex | C35: =-C29*Assumptions!$B$31 -> -7307.3419 | D35: =-D29*Assumptions!$B$31 -> -9864.9116 | E35: =-E29*Assumptions!$B$31 -> -11837.894 | F35: =-F29*Assumptions!$B$31 -> -13258.441 | G35: =-G29*Assumptions!$B$31 -> -14319.116
A36: Less: increase in working capital | C36: =-(C29-B29)*Assumptions!$B$32 -> -22803.053 | D36: =-(D29-C29)*Assumptions!$B$32 -> -17050.464 | E36: =-(E29-D29)*Assumptions!$B$32 -> -13153.215 | F36: =-(F29-E29)*Assumptions!$B$32 -> -9470.3151 | G36: =-(G29-F29)*Assumptions!$B$32 -> -7071.1686
A37: Unlevered free cash flow | C37: =C33+C34+C35+C36 -> 197147.94 | D37: =D33+D34+D35+D36 -> 279883.37 | E37: =E33+E34+E35+E36 -> 337708.81 | F37: =F33+F34+F35+F36 -> 377381.54 | G37: =G33+G34+G35+G36 -> 404126.13
A38: Less: 1H FY27 actual FCF (already realized) | C38: =-Assumptions!$B$33 -> -69895 | D38: 0 | E38: 0 | F38: 0 | G38: 0
A39: FCF to discount | C39: =C37+C38 -> 127252.94 | D39: =D37+D38 -> 279883.37 | E39: =E37+E38 -> 337708.81 | F39: =F37+F38 -> 377381.54 | G39: =G37+G38 -> 404126.13
A40: Discount period (years) | C40: =(C27-Assumptions!$B$4)/365 -> 0.33424658 | D40: =(D27-Assumptions!$B$4)/365 -> 1.3342466 | E40: =(E27-Assumptions!$B$4)/365 -> 2.3369863 | F40: =(F27-Assumptions!$B$4)/365 -> 3.3369863 | G40: =(G27-Assumptions!$B$4)/365 -> 4.3369863
A41: Discount factor | C41: =1/(1+Assumptions!$B$27)^C40 -> 0.96897063 | D41: =1/(1+Assumptions!$B$27)^D40 -> 0.88176868 | E41: =1/(1+Assumptions!$B$27)^E40 -> 0.80220713 | F41: =1/(1+Assumptions!$B$27)^F40 -> 0.73001296 | G41: =1/(1+Assumptions!$B$27)^G40 -> 0.66431587
A42: PV of FCF | C42: =C39*C41 -> 123304.36 | D42: =D39*D41 -> 246792.39 | E42: =E39*E41 -> 270912.41 | F42: =F39*F41 -> 275493.41 | G42: =G39*G41 -> 268467.4
...

Sheet DCF
A1: Discounted Cash Flow Valuation
A2: $ in millions except per share. Value as of the valuation date on the Assumptions sheet.
B3: Bear | C3: Base | D3: Bull
A4: PV of discrete FCF (2H FY27 - FY31) | B4: =SUM(Projections!C21:G21) -> 745834.57 | C4: =SUM(Projections!C42:G42) -> 1184970 | D4: =SUM(Projections!C63:G63) -> 1520562.4
A5: Terminal-year FCF (FY2031E) | B5: =Projections!G16 -> 187236.13 | C5: =Projections!G37 -> 404126.13 | D5: =Projections!G58 -> 571050.09
A6: Terminal growth rate | B6: =Assumptions!B52 -> 0.03 | C6: =Assumptions!C52 -> 0.035 | D6: =Assumptions!D52 -> 0.04
A7: WACC | B7: =Assumptions!$B$27 -> 0.098894363 | C7: =Assumptions!$B$27 -> 0.098894363 | D7: =Assumptions!$B$27 -> 0.098894363
A8: Terminal value at FY2031E | B8: =B5*(1+B6)/(B7-B6) -> 2799259.7 | C8: =C5*(1+C6)/(C7-C6) -> 6546282.4 | D8: =D5*(1+D6)/(D7-D6) -> 10084023
A9: Discount factor (FY2031E) | B9: =Projections!G20 -> 0.66431587 | C9: =Projections!G41 -> 0.66431587 | D9: =Projections!G62 -> 0.66431587
A10: PV of terminal value | B10: =B8*B9 -> 1859592.6 | C10: =C8*C9 -> 4348799.2 | D10: =D8*D9 -> 6698976.3
A11: Enterprise value | B11: =B4+B10 -> 2605427.2 | C11: =C4+C10 -> 5533769.2 | D11: =D4+D10 -> 8219538.7
A12: Plus: net cash & investments (adjusted) | B12: =Assumptions!$B$16 -> 91581.5 | C12: =Assumptions!$B$16 -> 91581.5 | D12: =Assumptions!$B$16 -> 91581.5
A13: Equity value | B13: =B11+B12 -> 2697008.7 | C13: =C11+C12 -> 5625350.7 | D13: =D11+D12 -> 8311120.2
A14: Diluted shares (mm) | B14: =Assumptions!$B$6 -> 24260 | C14: =Assumptions!$B$6 -> 24260 | D14: =Assumptions!$B$6 -> 24260
A15: DCF value per share ($) | B15: =B13/B14 -> 111.17101 | C15: =C13/C14 -> 231.87761 | D15: =D13/D14 -> 342.58533
A16: Current price ($) | B16: =Assumptions!$B$5 -> 228.38 | C16: =Assumptions!$B$5 -> 228.38 | D16: =Assumptions!$B$5 -> 228.38
A17: Upside / (downside) vs. price | B17: =B15/B16-1 -> -0.51321915 | C17: =C15/C16-1 -> 0.015314853 | D17: =D15/D16-1 -> 0.50006715
A18: Terminal value as % of EV | B18: =B10/B11 -> 0.71373809 | C18: =C10/C11 -> 0.78586567 | D18: =D10/D11 -> 0.81500635
A19: Implied terminal EV / EBIT (x) | B19: =B8/Projections!G10 -> 12.418295 | C19: =C8/Projections!G31 -> 13.062024 | D19: =D8/Projections!G52 -> 14.152216
A22: Sensitivity - Base case DCF value per share ($): WACC (down) vs. terminal growth (across)
A23: WACC \ Terminal growth | B23: =$C$6+(-0.01) -> 0.025 | C23: =$C$6+(-0.005) -> 0.03 | D23: =$C$6+(0) -> 0.035 | E23: =$C$6+(0.005) -> 0.04 | F23: =$C$6+(0.01) -> 0.045
A24: =$C$7+(-0.015) -> 0.083894363 | B24: =(SUMPRODUCT(Projections!$C$39:$G$39/(1+$A24)^Projections!$C$40:$G$40)+Projections!$G$37*(1+B$23)/($A24-B$23)/(1+$A24)^Projections!$G$40+Assumptions!$B$16)/Assumptions!$B$6 -> 258.83545 | C24: =(SUMPRODUCT(Projections!$C$39:$G$39/(1+$A24)^Projections!$C$40:$G$40)+Projections!$G$37*(1+C$23)/($A24-C$23)/(1+$A24)^Projections!$G$40+Assumptions!$B$16)/Assumptions!$B$6 -> 278.8907 | D24: =(SUMPRODUCT(Projections!$C$39:$G$39/(1+$A24)^Projections!$C$40:$G$40)+Projections!$G$37*(1+D$23)/($A24-D$23)/(1+$A24)^Projections!$G$40+Assumptions!$B$16)/Assumptions!$B$6 -> 303.0477 | E24: =(SUMPRODUCT(Projections!$C$39:$G$39/(1+$A24)^Projections!$C$40:$G$40)+Projections!$G$37*(1+E$23)/($A24-E$23)/(1+$A24)^Projections!$G$40+Assumptions!$B$16)/Assumptions!$B$6 -> 332.70814 | F24: =(SUMPRODUCT(Projections!$C$39:$G$39/(1+$A24)^Projections!$C$40:$G$40)+Projections!$G$37*(1+F$23)/($A24-F$23)/(1+$A24)^Projections!$G$40+Assumptions!$B$16)/Assumptions!$B$6 -> 369.99448
A25: =$C$7+(-0.01) -> 0.088894363 | B25: =(SUMPRODUCT(Projections!$C$39:$G$39/(1+$A25)^Projections!$C$40:$G$40)+Projections!$G$37*(1+B$23)/($A25-B$23)/(1+$A25)^Projections!$G$40+Assumptions!$B$16)/Assumptions!$B$6 -> 238.50635 | C25: =(SUMPRODUCT(Projections!$C$39:$G$39/(1+$A25)^Projections!$C$40:$G$40)+Projections!$G$37*(1+C$23)/($A25-C$23)/(1+$A25)^Projections!$G$40+Assumptions!$B$16)/Assumptions!$B$6 -> 255.16497 | D25: =(SUMPRODUCT(Projections!$C$39:$G$39/(1+$A25)^Projections!$C$40:$G$40)+Projections!$G$37*(1+D$23)/($A25-D$23)/(1+$A25)^Projections!$G$40+Assumptions!$B$16)/Assumptions!$B$6 -> 274.91456 | E25: =(SUMPRODUCT(Projections!$C$39:$G$39/(1+$A25)^Projections!$C$40:$G$40)+Projections!$G$37*(1+E$23)/($A25-E$23)/(1+$A25)^Projections!$G$40+Assumptions!$B$16)/Assumptions!$B$6 -> 298.70339 | F25: =(SUMPRODUCT(Projections!$C$39:$G$39/(1+$A25)^Projections!$C$40:$G$40)+Projections!$G$37*(1+F$23)/($A25-F$23)/(1+$A25)^Projections!$G$40+Assumptions!$B$16)/Assumptions!$B$6 -> 327.91178
A26: =$C$7+(-0.005) -> 0.093894363 | B26: =(SUMPRODUCT(Projections!$C$39:$G$39/(1+$A26)^Projections!$C$40:$G$40)+Projections!$G$37*(1+B$23)/($A26-B$23)/(1+$A26)^Projections!$G$40+Assumptions!$B$16)/Assumptions!$B$6 -> 221.13517 | C26: =(SUMPRODUCT(Projections!$C$39:$G$39/(1+$A26)^Projections!$C$40:$G$40)+Projections!$G$37*(1+C$23)/($A26-C$23)/(1+$A26)^Projections!$G$40+Assumptions!$B$16)/Assumptions!$B$6 -> 235.15974 | D26: =(SUMPRODUCT(Projections!$C$39:$G$39/(1+$A26)^Projections!$C$40:$G$40)+Projections!$G$37*(1+D$23)/($A26-D$23)/(1+$A26)^Projections!$G$40+Assumptions!$B$16)/Assumptions!$B$6 -> 251.56562 | E26: =(SUMPRODUCT(Projections!$C$39:$G$39/(1+$A26)^Projections!$C$40:$G$40)+Projections!$G$37*(1+E$23)/($A26-E$23)/(1+$A26)^Projections!$G$40+Assumptions!$B$16)/Assumptions!$B$6 -> 271.01559 | F26: =(SUMPRODUCT(Projections!$C$39:$G$39/(1+$A26)^Projections!$C$40:$G$40)+Projections!$G$37*(1+F$23)/($A26-F$23)/(1+$A26)^Projections!$G$40+Assumptions!$B$16)/Assumptions!$B$6 -> 294.4435
A27: =$C$7+(0) -> 0.098894363 | B27: =(SUMPRODUCT(Projections!$C$39:$G$39/(1+$A27)^Projections!$C$40:$G$40)+Projections!$G$37*(1+B$23)/($A27-B$23)/(1+$A27)^Projections!$G$40+Assumptions!$B$16)/Assumptions!$B$6 -> 206.12134 | C27: =(SUMPRODUCT(Projections!$C$39:$G$39/(1+$A27)^Projections!$C$40:$G$40)+Projections!$G$37*(1+C$23)/($A27-C$23)/(1+$A27)^Projections!$G$40+Assumptions!$B$16)/Assumptions!$B$6 -> 218.06485 | D27: =(SUMPRODUCT(Projections!$C$39:$G$39/(1+$A27)^Projections!$C$40:$G$40)+Projections!$G$37*(1+D$23)/($A27-D$23)/(1+$A27)^Projections!$G$40+Assumptions!$B$16)/Assumptions!$B$6 -> 231.87761 | E27: =(SUMPRODUCT(Projections!$C$39:$G$39/(1+$A27)^Projections!$C$40:$G$40)+Projections!$G$37*(1+E$23)/($A27-E$23)/(1+$A27)^Projections!$G$40+Assumptions!$B$16)/Assumptions!$B$6 -> 248.03571 | F27: =(SUMPRODUCT(Projections!$C$39:$G$39/(1+$A27)^Projections!$C$40:$G$40)+Projections!$G$37*(1+F$23)/($A27-F$23)/(1+$A27)^Projections!$G$40+Assumptions!$B$16)/Assumptions!$B$6 -> 267.19192
A28: =$C$7+(0.005) -> 0.10389436 | B28: =(SUMPRODUCT(Projections!$C$39:$G$39/(1+$A28)^Projections!$C$40:$G$40)+Projections!$G$37*(1+B$23)/($A28-B$23)/(1+$A28)^Projections!$G$40+Assumptions!$B$16)/Assumptions!$B$6 -> 193.01655 | C28: =(SUMPRODUCT(Projections!$C$39:$G$39/(1+$A28)^Projections!$C$40:$G$40)+Projections!$G$37*(1+C$23)/($A28-C$23)/(1+$A28)^Projections!$G$40+Assumptions!$B$16)/Assumptions!$B$6 -> 203.28938 | D28: =(SUMPRODUCT(Projections!$C$39:$G$39/(1+$A28)^Projections!$C$40:$G$40)+Projections!$G$37*(1+D$23)/($A28-D$23)/(1+$A28)^Projections!$G$40+Assumptions!$B$16)/Assumptions!$B$6 -> 215.05332 | E28: =(SUMPRODUCT(Projections!$C$39:$G$39/(1+$A28)^Projections!$C$40:$G$40)+Projections!$G$37*(1+E$23)/($A28-E$23)/(1+$A28)^Projections!$G$40+Assumptions!$B$16)/Assumptions!$B$6 -> 228.65841 | F28: =(SUMPRODUCT(Projections!$C$39:$G$39/(1+$A28)^Projections!$C$40:$G$40)+Projections!$G$37*(1+F$23)/($A28-F$23)/(1+$A28)^Projections!$G$40+Assumptions!$B$16)/Assumptions!$B$6 -> 244.57358
A29: =$C$7+(0.01) -> 0.10889436 | B29: =(SUMPRODUCT(Projections!$C$39:$G$39/(1+$A29)^Projections!$C$40:$G$40)+Projections!$G$37*(1+B$23)/($A29-B$23)/(1+$A29)^Projections!$G$40+Assumptions!$B$16)/Assumptions!$B$6 -> 181.47935 | C29: =(SUMPRODUCT(Projections!$C$39:$G$39/(1+$A29)^Projections!$C$40:$G$40)+Projections!$G$37*(1+C$23)/($A29-C$23)/(1+$A29)^Projections!$G$40+Assumptions!$B$16)/Assumptions!$B$6 -> 190.39225 | D29: =(SUMPRODUCT(Projections!$C$39:$G$39/(1+$A29)^Projections!$C$40:$G$40)+Projections!$G$37*(1+D$23)/($A29-D$23)/(1+$A29)^Projections!$G$40+Assumptions!$B$16)/Assumptions!$B$6 -> 200.51133 | E29: =(SUMPRODUCT(Projections!$C$39:$G$39/(1+$A29)^Projections!$C$40:$G$40)+Projections!$G$37*(1+E$23)/($A29-E$23)/(1+$A29)^Projections!$G$40+Assumptions!$B$16)/Assumptions!$B$6 -> 212.09919 | F29: =(SUMPRODUCT(Projections!$C$39:$G$39/(1+$A29)^Projections!$C$40:$G$40)+Projections!$G$37*(1+F$23)/($A29-F$23)/(1+$A29)^Projections!$G$40+Assumptions!$B$16)/Assumptions!$B$6 -> 225.50065
A30: =$C$7+(0.015) -> 0.11389436 | B30: =(SUMPRODUCT(Projections!$C$39:$G$39/(1+$A30)^Projections!$C$40:$G$40)+Projections!$G$37*(1+B$23)/($A30-B$23)/(1+$A30)^Projections!$G$40+Assumptions!$B$16)/Assumptions!$B$6 -> 171.24512 | C30: =(SUMPRODUCT(Projections!$C$39:$G$39/(1+$A30)^Projections!$C$40:$G$40)+Projections!$G$37*(1+C$23)/($A30-C$23)/(1+$A30)^Projections!$G$40+Assumptions!$B$16)/Assumptions!$B$6 -> 179.03752 | D30: =(SUMPRODUCT(Projections!$C$39:$G$39/(1+$A30)^Projections!$C$40:$G$40)+Projections!$G$37*(1+D$23)/($A30-D$23)/(1+$A30)^Projections!$G$40+Assumptions!$B$16)/Assumptions!$B$6 -> 187.81763 | E30: =(SUMPRODUCT(Projections!$C$39:$G$39/(1+$A30)^Projections!$C$40:$G$40)+Projections!$G$37*(1+E$23)/($A30-E$23)/(1+$A30)^Projections!$G$40+Assumptions!$B$16)/Assumptions!$B$6 -> 197.78592 | F30: =(SUMPRODUCT(Projections!$C$39:$G$39/(1+$A30)^Projections!$C$40:$G$40)+Projections!$G$37*(1+F$23)/($A30-F$23)/(1+$A30)^Projections!$G$40+Assumptions!$B$16)/Assumptions!$B$6 -> 209.20112
A32: Centre cell (WACC and g at base values) equals the Base DCF value per share above.
A34: Sensitivity - Base case upside / (downside) vs. current price
A35: WACC \ Terminal growth | B35: =B23 -> 0.025 | C35: =C23 -> 0.03 | D35: =D23 -> 0.035 | E35: =E23 -> 0.04 | F35: =F23 -> 0.045
A36: =A24 -> 0.083894363 | B36: =B24/Assumptions!$B$5-1 -> 0.13335428 | C36: =C24/Assumptions!$B$5-1 -> 0.22116955 | D36: =D24/Assumptions!$B$5-1 -> 0.32694501 | E36: =E24/Assumptions!$B$5-1 -> 0.45681821 | F36: =F24/Assumptions!$B$5-1 -> 0.62008267
A37: =A25 -> 0.088894363 | B37: =B25/Assumptions!$B$5-1 -> 0.044339931 | C37: =C25/Assumptions!$B$5-1 -> 0.11728247 | D37: =D25/Assumptions!$B$5-1 -> 0.20375936 | E37: =E25/Assumptions!$B$5-1 -> 0.30792272 | F37: =F25/Assumptions!$B$5-1 -> 0.43581655
A38: =A26 -> 0.093894363 | B38: =B26/Assumptions!$B$5-1 -> -0.031722687 | C38: =C26/Assumptions!$B$5-1 -> 0.029686241 | D38: =D26/Assumptions!$B$5-1 -> 0.10152213 | E38: =E26/Assumptions!$B$5-1 -> 0.18668704 | F38: =F26/Assumptions!$B$5-1 -> 0.28927009
A39: =A27 -> 0.098894363 | B39: =B27/Assumptions!$B$5-1 -> -0.097463249 | C39: =C27/Assumptions!$B$5-1 -> -0.045166626 | D39: =D27/Assumptions!$B$5-1 -> 0.015314853 | E39: =E27/Assumptions!$B$5-1 -> 0.086065819 | F39: =F27/Assumptions!$B$5-1 -> 0.1699445
A40: =A28 -> 0.10389436 | B40: =B28/Assumptions!$B$5-1 -> -0.15484479 | C40: =C28/Assumptions!$B$5-1 -> -0.10986346 | D40: =D28/Assumptions!$B$5-1 -> -0.058353109 | E40: =E28/Assumptions!$B$5-1 -> 0.001219045 | F40: =F28/Assumptions!$B$5-1 -> 0.070906285
A41: =A29 -> 0.10889436 | B41: =B29/Assumptions!$B$5-1 -> -0.20536235 | C41: =C29/Assumptions!$B$5-1 -> -0.16633569 | D41: =D29/Assumptions!$B$5-1 -> -0.12202762 | E41: =E29/Assumptions!$B$5-1 -> -0.071288235 | F41: =F29/Assumptions!$B$5-1 -> -0.012607718
A42: =A30 -> 0.11389436 | B42: =B30/Assumptions!$B$5-1 -> -0.25017461 | C42: =C30/Assumptions!$B$5-1 -> -0.21605428 | D42: =D30/Assumptions!$B$5-1 -> -0.17760913 | E42: =E30/Assumptions!$B$5-1 -> -0.13396127 | F42: =F30/Assumptions!$B$5-1 -> -0.083977932

Sheet Valuation
A1: Relative Valuation - Current Multiples & Forward P/E Value
A2: $ in millions except per share.
A3: Current trading multiples (TTM to Jul-2026, GAAP)
A4: Market cap | B4: =Assumptions!B7 -> 5540498.8
A5: Enterprise value | B5: =Assumptions!B17 -> 5448917.3
A6: TTM revenue | B6: =Historical!G5 -> 302970
A7: TTM operating income | B7: =Historical!G8 -> 197579
A8: TTM net income | B8: =Historical!G9 -> 192880
A9: P/E (TTM, GAAP) | B9: =B4/B8 -> 28.725108 | E9: TTM GAAP net income includes large gains on equity securities; forward P/E is cleaner.
A10: EV / TTM revenue | B10: =B5/B6 -> 17.985006
A11: EV / TTM EBIT | B11: =B5/B7 -> 27.578423
A12: TTM operating margin | B12: =B7/B6 -> 0.65214048
A13: P/E on FY2027E EPS (Base) | B13: =Assumptions!B5/Projections!C44 -> 24.913797
A14: P/E on FY2028E EPS (Base) | B14: =Assumptions!B5/Projections!D44 -> 18.454664
A16: Forward P/E-based value by scenario
B17: Bear | C17: Base | D17: Bull
A18: FY2028E EPS ($) | B18: =Projections!D23 -> 9.2776257 | C18: =Projections!D44 -> 12.375191 | D18: =Projections!D65 -> 14.61902
A19: Target forward P/E (x) | B19: =Assumptions!B53 -> 14 | C19: =Assumptions!C53 -> 22 | D19: =Assumptions!D53 -> 28
A20: 12-month price target ($) | B20: =B18*B19 -> 129.88676 | C20: =C18*C19 -> 272.25421 | D20: =D18*D19 -> 409.33257 | E20: Price a year out if the market applies the target multiple to FY2028E EPS
A21: Discount to today at cost of equity | B21: =1/(1+Assumptions!$B$23) -> 0.90971117 | C21: =1/(1+Assumptions!$B$23) -> 0.90971117 | D21: =1/(1+Assumptions!$B$23) -> 0.90971117
A22: P/E-based value today ($) | B22: =B20*B21 -> 118.15944 | C22: =C20*C21 -> 247.6727 | D22: =D20*D21 -> 372.37441
A23: Upside / (downside) vs. price | B23: =B22/Assumptions!$B$5-1 -> -0.48261916 | C23: =C22/Assumptions!$B$5-1 -> 0.084476291 | D23: =D22/Assumptions!$B$5-1 -> 0.63050359

Sheet Sources
A1: Sources & Notes
A3: DATA SOURCES
A4: NVIDIA Form 8-K / press release, Q4 & FY2026 (25-Feb-2026): sec.gov / investor.nvidia.com - FY2026 revenue $215,938mm, operating income $130,387mm, net income $120,067mm, FY2025 comparatives.
A5: NVIDIA Form 8-K / press release & CFO commentary, Q2 FY2027 (26-Aug-2026): revenue $96,221mm, GAAP net income $59,688mm, GAAP EPS $2.46, balance sheet, cash flow, Q3 guidance $108bn +/-2%.
A6: NVIDIA press release, Q1 FY2027: Q1 FCF $48,554mm; balance sheet at 26-Apr-2026.
A7: FY2024 figures from NVIDIA FY2024 Form 10-K (revenue $60,922mm, operating income $32,972mm, net income $29,760mm); FY2024/FY2025 FCF from 10-K cash flow statements.
A8: Share price / market data: Yahoo Finance and Motley Fool quotes (30-Sep / 1-Oct-2026): close $228.38; 52-week range $164.27-$236.54; analyst target range $180-$515 (avg ~$328).
A9: The Financial Datasets connector returned an out-of-credits error, so no data was taken from it.
A11: KEY MODELING NOTES
A12: 1. DCF uses unlevered FCF = EBIT x (1 - tax) + D&A - capex - working-capital build. Stock-based compensation is treated as a real cost (GAAP operating income).
A13: 2. FY2027E FCF less actual 1H FY27 FCF ($69.9bn) is discounted as a 2H FY27 stub; balance-sheet cash is as of 26-Jul-2026, so no double counting.
A14: 3. Equity stakes (marketable at 100%, non-marketable at 50%) are added to net cash; set both to 0% on Assumptions to see the operating business only.
... A18: 7. Educational analysis only; not investment advice. Verify all inputs before acting.
